<sdf version='1.6'>
  <model name='hopper'>
    <link name='mid'>
      <pose frame=''>0 0 0 0 -0 0</pose>
      <inertial>
        <pose frame=''>0 0 0 0 -0 0</pose>
        <mass>0.0001</mass>
        <inertia>
          <ixx>0</ixx>
          <ixy>0</ixy>
          <ixz>0</ixz>
          <iyy>0</iyy>
          <iyz>0</iyz>
          <izz>0</izz>
        </inertia>
      </inertial>
    </link>
    <joint name='world_to_mid' type='prismatic'>
      <child>mid</child>
      <parent>world</parent>
      <axis>
        <xyz>1 0 0</xyz>
        <limit>
          <lower>-1</lower>
          <upper>1000</upper>
          <effort>10000</effort>
          <velocity>1000</velocity>
        </limit>
        <dynamics>
          <spring_reference>0</spring_reference>
          <spring_stiffness>0</spring_stiffness>
        </dynamics>
        <use_parent_model_frame>1</use_parent_model_frame>
      </axis>
    </joint>
    <link name='mid2'>
      <pose frame=''>0 0 1.23 0 -0 0</pose>
      <inertial>
        <pose frame=''>0 0 0 0 -0 0</pose>
        <mass>0.0001</mass>
        <inertia>
          <ixx>0</ixx>
          <ixy>0</ixy>
          <ixz>0</ixz>
          <iyy>0</iyy>
          <iyz>0</iyz>
          <izz>0</izz>
        </inertia>
      </inertial>
    </link>
    <joint name='mid_to_mid2' type='prismatic'>
      <child>mid2</child>
      <parent>mid</parent>
      <axis>
        <xyz>0 0 1</xyz>
        <limit>
          <lower>-10</lower>
          <upper>1000</upper>
          <effort>10000</effort>
          <velocity>1000</velocity>
        </limit>
        <dynamics>
          <spring_reference>0</spring_reference>
          <spring_stiffness>0</spring_stiffness>
        </dynamics>
        <use_parent_model_frame>1</use_parent_model_frame>
      </axis>
    </joint>
    <link name='torso'>
      <pose frame=''>0 0 1.23 0 -0 0</pose>
      <inertial>
        <pose frame=''>0 0 0 0 -0 0</pose>
        <mass>3.14159</mass>
        <inertia>
          <ixx>0.0438514</ixx>
          <ixy>0</ixy>
          <ixz>0</ixz>
          <iyy>0.0438514</iyy>
          <iyz>0</iyz>
          <izz>0.000654498</izz>
        </inertia>
      </inertial>
      <collision name='torso_collision'>
        <pose frame=''>0 0 0 0 -0 0</pose>
        <geometry>
          <cylinder>
            <length>0.4</length>
            <radius>0.05</radius>
          </cylinder>
        </geometry>
        <surface>
          <contact>
            <ode/>
          </contact>
          <friction>
            <ode/>
          </friction>
        </surface>
      </collision>
      <visual name='torso_visual'>
        <pose frame=''>0 0 0 0 -0 0</pose>
        <geometry>
          <cylinder>
            <length>0.4</length>
            <radius>0.05</radius>
          </cylinder>
        </geometry>
        <material>
          <script>
            <name>Gazebo/Red</name>
            <uri>file://media/materials/scripts/gazebo.material</uri>
          </script>
        </material>
      </visual>
      <gravity>1</gravity>
      <velocity_decay/>
    </link>
    <joint name='mid2_to_torso' type='revolute'>
      <child>torso</child>
      <parent>mid2</parent>
      <axis>
        <xyz>0 1 0</xyz>
        <limit>
          <lower>-1e+16</lower>
          <upper>1e+16</upper>
        </limit>
        <dynamics>
          <spring_reference>0</spring_reference>
          <spring_stiffness>0</spring_stiffness>
        </dynamics>
        <use_parent_model_frame>1</use_parent_model_frame>
      </axis>
    </joint>
    <link name='thigh'>
      <pose frame=''>0 0 1.03 0 -0 0</pose>
      <inertial>
        <pose frame=''>0 0 -0.225 0 -0 0</pose>
        <mass>3.53429</mass>
        <inertia>
          <ixx>0.0618501</ixx>
          <ixy>0</ixy>
          <ixz>0</ixz>
          <iyy>0.0618501</iyy>
          <iyz>0</iyz>
          <izz>0.00073631</izz>
        </inertia>
      </inertial>
      <collision name='thigh_collision'>
        <pose frame=''>0 0 -0.225 0 -0 0</pose>
        <geometry>
          <cylinder>
            <length>0.45</length>
            <radius>0.05</radius>
          </cylinder>
        </geometry>
        <surface>
          <contact>
            <ode/>
          </contact>
          <friction>
            <ode/>
          </friction>
        </surface>
      </collision>
      <visual name='thigh_visual'>
        <pose frame=''>0 0 -0.225 0 -0 0</pose>
        <geometry>
          <cylinder>
            <length>0.45</length>
            <radius>0.05</radius>
          </cylinder>
        </geometry>
        <material>
          <script>
            <name>Gazebo/Green</name>
            <uri>file://media/materials/scripts/gazebo.material</uri>
          </script>
        </material>
      </visual>
      <gravity>1</gravity>
      <velocity_decay/>
    </link>
    <joint name='torso_to_thigh' type='revolute'>
      <child>thigh</child>
      <parent>torso</parent>
      <axis>
        <xyz>0 1 0</xyz>
        <limit>
          <lower>0</lower>
          <upper>2.61799</upper>
          <effort>1000</effort>
          <velocity>0.5</velocity>
        </limit>
        <dynamics>
          <spring_reference>0</spring_reference>
          <spring_stiffness>0</spring_stiffness>
        </dynamics>
        <use_parent_model_frame>1</use_parent_model_frame>
      </axis>
    </joint>
    <link name='leg'>
      <pose frame=''>0 0 0.58 0 -0 0</pose>
      <inertial>
        <pose frame=''>0 0 -0.25 0 -0 0</pose>
        <mass>2.51327</mass>
        <inertia>
          <ixx>0.0533651</ixx>
          <ixy>0</ixy>
          <ixz>0</ixz>
          <iyy>0.0533651</iyy>
          <iyz>0</iyz>
          <izz>0.000335103</izz>
        </inertia>
      </inertial>
      <collision name='leg_collision'>
        <pose frame=''>0 0 -0.25 0 -0 0</pose>
        <geometry>
          <cylinder>
            <length>0.5</length>
            <radius>0.04</radius>
          </cylinder>
        </geometry>
        <surface>
          <contact>
            <ode/>
          </contact>
          <friction>
            <ode/>
          </friction>
        </surface>
      </collision>
      <visual name='leg_visual'>
        <pose frame=''>0 0 -0.25 0 -0 0</pose>
        <geometry>
          <cylinder>
            <length>0.5</length>
            <radius>0.04</radius>
          </cylinder>
        </geometry>
        <material>
          <script>
            <name>Gazebo/Blue</name>
            <uri>file://media/materials/scripts/gazebo.material</uri>
          </script>
        </material>
      </visual>
      <gravity>1</gravity>
      <velocity_decay/>
    </link>
    <joint name='thigh_to_leg' type='revolute'>
      <child>leg</child>
      <parent>thigh</parent>
      <axis>
        <xyz>0 1 0</xyz>
        <limit>
          <lower>0</lower>
          <upper>2.61799</upper>
          <effort>1000</effort>
          <velocity>0.5</velocity>
        </limit>
        <dynamics>
          <spring_reference>0</spring_reference>
          <spring_stiffness>0</spring_stiffness>
        </dynamics>
        <use_parent_model_frame>1</use_parent_model_frame>
      </axis>
    </joint>
    <link name='foot'>
      <pose frame=''>0 0 0.08 0 -0 0</pose>
      <inertial>
        <pose frame=''>0.065 0 0 3.14159 1.57079 3.14159</pose>
        <mass>4.41079</mass>
        <inertia>
          <ixx>0.0598765</ixx>
          <ixy>0</ixy>
          <ixz>0</ixz>
          <iyy>0.0598765</iyy>
          <iyz>0</iyz>
          <izz>0.00132324</izz>
        </inertia>
      </inertial>
      <collision name='foot_collision'>
        <pose frame=''>0.065 0 0 3.14159 1.57079 3.14159</pose>
        <geometry>
          <cylinder>
            <length>0.39</length>
            <radius>0.06</radius>
          </cylinder>
        </geometry>
        <surface>
          <contact>
            <ode/>
          </contact>
          <friction>
            <ode>
              <mu>1</mu>
              <mu2>1</mu2>
            </ode>
          </friction>
        </surface>
      </collision>
      <collision name='foot_collision_1'>
        <pose frame=''>0.26 0 0 3.14159 1.57079 3.14159</pose>
        <geometry>
          <sphere>
            <radius>0.06</radius>
          </sphere>
        </geometry>
        <surface>
          <contact>
            <ode/>
          </contact>
          <friction>
            <ode>
              <mu>1</mu>
              <mu2>1</mu2>
            </ode>
          </friction>
        </surface>
      </collision>
      <collision name='foot_collision_2'>
        <pose frame=''>-0.13 0 0 3.14159 1.57079 3.14159</pose>
        <geometry>
          <sphere>
            <radius>0.06</radius>
          </sphere>
        </geometry>
        <surface>
          <contact>
            <ode/>
          </contact>
          <friction>
            <ode>
              <mu>1</mu>
              <mu2>1</mu2>
            </ode>
          </friction>
        </surface>
      </collision>
      <visual name='foot_visual'>
        <pose frame=''>0.065 0 0 3.14159 1.57079 3.14159</pose>
        <geometry>
          <cylinder>
            <length>0.39</length>
            <radius>0.06</radius>
          </cylinder>
        </geometry>
        <material>
          <script>
            <name>Gazebo/Grey</name>
            <uri>file://media/materials/scripts/gazebo.material</uri>
          </script>
        </material>
      </visual>
      <visual name='foot_visual_1'>
        <pose frame=''>0.26 0 0 3.14159 1.57079 3.14159</pose>
        <geometry>
          <sphere>
            <radius>0.06</radius>
          </sphere>
        </geometry>
        <material>
          <script>
            <name>Gazebo/Grey</name>
            <uri>file://media/materials/scripts/gazebo.material</uri>
          </script>
        </material>
      </visual>
      <visual name='foot_visual_2'>
        <pose frame=''>-0.13 0 0 3.14159 1.57079 3.14159</pose>
        <geometry>
          <sphere>
            <radius>0.06</radius>
          </sphere>
        </geometry>
        <material>
          <script>
            <name>Gazebo/Grey</name>
            <uri>file://media/materials/scripts/gazebo.material</uri>
          </script>
        </material>
      </visual>
      <gravity>1</gravity>
      <velocity_decay/>
    </link>
    <joint name='leg_to_foot' type='revolute'>
      <child>foot</child>
      <parent>leg</parent>
      <axis>
        <xyz>0 1 0</xyz>
        <limit>
          <lower>-0.785397</lower>
          <upper>0.785397</upper>
          <effort>1000</effort>
          <velocity>0.5</velocity>
        </limit>
        <dynamics>
          <spring_reference>0</spring_reference>
          <spring_stiffness>0</spring_stiffness>
        </dynamics>
        <use_parent_model_frame>1</use_parent_model_frame>
      </axis>
    </joint>
  </model>
</sdf>
