<?xml version='1.0'?>
<!--
  Desribes the hopper "robot" n SDF format. SDF is more generic and can provide more information than URDF, but ROS does not
  support it well. In particular robot_state_publisher only supports URDF.
  This file is only kept as a reference. In the future there may be a sdf-to-urdf converter, in that case we could only write
  SDF files and then generate the URDF ones if needed (see https://github.com/osrf/gazebo/issues/1482)
-->
<sdf version='1.4'>
  <model name="hopper">
    <static>false</static>
    <link name='torso'>
    <pose>0.0 0.0 1.25 0.0 0.0 0.0</pose>

      <inertial>
        <pose>0.0 0.0 0.0 0 0.0 0.0</pose>
        <mass>4</mass>
        <!-- Link mass is centered -->
        <inertia>
          <ixx>0.01</ixx>
          <ixy>0.0</ixy>
          <ixz>0.0</ixz>
          <iyy>0.01</iyy>
          <iyz>0.0</iyz>
          <izz>0.01</izz>
        </inertia>
      </inertial>

      <collision name='torso_collision'>
        <pose>0.0 0.0 0.0 0 0.0 0.0</pose>
        <geometry>
          <cylinder>
            <length>0.40</length>
            <radius>0.05</radius>
          </cylinder>
        </geometry>
      </collision>

      <visual name='torso_visual'>
        <pose>0.0 0.0 0.0 0.0 0.0 0.0</pose>
        <geometry>
          <cylinder>
            <length>0.40</length>
            <radius>0.05</radius>
          </cylinder>
        </geometry>
      </visual>
    </link>






    <link name='thigh'>
    <pose>0.0 0.0 0.825 0.0 0.0 0.0</pose>

      <inertial>
        <pose>0.0 0.0 0.0 0 0.0 0.0</pose>
        <mass>3</mass>
        <!-- Link mass is centered -->
        <inertia>
          <ixx>0.01</ixx>
          <ixy>0.0</ixy>
          <ixz>0.0</ixz>
          <iyy>0.01</iyy>
          <iyz>0.0</iyz>
          <izz>0.01</izz>
        </inertia>
      </inertial>

      <collision name='thigh_collision'>
        <pose>0.0 0.0 0.0 0 0.0 0.0</pose>
        <geometry>
          <cylinder>
            <length>0.45</length>
            <radius>0.05</radius>
          </cylinder>
        </geometry>
      </collision>

      <visual name='thigh_visual'>
        <pose>0.0 0.0 0.0 0 0.0 0.0</pose>
        <geometry>
          <cylinder>
            <length>0.45</length>
            <radius>0.05</radius>
          </cylinder>
        </geometry>
      </visual>
    </link>
    <joint type="revolute" name="hip">
      <pose>0 0 0.225 0 0 0</pose>
      <child>thigh</child>
      <parent>torso</parent>
      <axis>
        <xyz> 0 1 0 </xyz>
        <limit>
          <lower> 0 </lower>
          <upper> 2.617991667 </upper>
          <velocity> 0.5 </velocity>
          <effort> 1000 </effort>
        </limit>
      </axis>
    </joint>








    <link name='leg'>
    <pose>0.0 0.0 0.35 0.0 0.0 0.0</pose>

      <inertial>
        <pose>0.0 0.0 0.0 0 0.0 0.0</pose>
        <mass>2.5</mass>
        <!-- Link mass is centered -->
        <inertia>
          <ixx>0.01</ixx>
          <ixy>0.0</ixy>
          <ixz>0.0</ixz>
          <iyy>0.01</iyy>
          <iyz>0.0</iyz>
          <izz>0.01</izz>
        </inertia>
      </inertial>

      <collision name='leg_collision'>
        <pose>0.0 0.0 0 0 0.0 0.0</pose>
        <geometry>
          <cylinder>
            <length>0.50</length>
            <radius>0.04</radius>
          </cylinder>
        </geometry>
      </collision>

      <visual name='leg_visual'>
        <pose>0.0 0.0 0 0 0.0 0.0</pose>
        <geometry>
          <cylinder>
            <length>0.50</length>
            <radius>0.04</radius>
          </cylinder>
        </geometry>
      </visual>
    </link>
    <joint type="revolute" name="knee">
      <pose>0 0 0.25 0 0 1.57</pose>
      <child>leg</child>
      <parent>thigh</parent>
      <axis>
        <xyz> 0 1 0 </xyz>
        <limit>
          <lower> 0 </lower>
          <upper> 2.617991667 </upper>
          <velocity> 0.5 </velocity>
          <effort> 1000 </effort>
        </limit>
      </axis>
    </joint>








    <link name='foot'>
    <pose>0.065 0.0 0.1 0.0 0.0 0.0</pose>

      <inertial>
        <mass>1</mass>
        <pose>0.0 0.0 0.0 0.0 0.0 0.0</pose>
        <!-- Link mass is centered -->
        <inertia>
          <ixx>0.01</ixx>
          <ixy>0.0</ixy>
          <ixz>0.0</ixz>
          <iyy>0.01</iyy>
          <iyz>0.0</iyz>
          <izz>0.01</izz>
        </inertia>
      </inertial>

      <collision name='foot_collision'>
        <pose>0.0 0.0 0.0 0 -1.570796 0.0</pose>
        <geometry>
          <cylinder>
            <length>0.39</length>
            <radius>0.06</radius>
          </cylinder>
        </geometry>
        <surface>
          <friction>
            <bullet>
              <friction> 0.6 </friction>
              <friction2> 0.6 </friction2>
              <fdir1> 0 0 0 </fdir1>
              <rolling_friction> 1 </rolling_friction>
            </bullet>
          </friction>
        </surface>
      </collision>

      <visual name='foot_visual'>
        <pose>0.0 0.0 0.0 0 -1.570796 0.0</pose>
        <geometry>
          <cylinder>
            <length>0.39</length>
            <radius>0.06</radius>
          </cylinder>
        </geometry>
      </visual>
    </link>
    <joint type="revolute" name="ankle">
      <pose>-0.065 0 0 0 0 0</pose>
      <child>foot</child>
      <parent>leg</parent>
      <axis>
        <xyz> 0 1 0 </xyz>
        <limit>
          <lower> -0.7853975 </lower>
          <upper> 0.7853975 </upper>
          <velocity> 0.5 </velocity>
          <effort> 1000 </effort>
        </limit>
      </axis>
    </joint>


  </model>
</sdf>
